Workbook

Sheet Imagen_Original
A1: 255 | B1: 255 | C1: 255 | D1: 255 | E1: 255 | F1: 255 | G1: 255 | H1: 255 | I1: 255 | J1: 255 | K1: 255 | L1: 255 | M1: 255 | N1: 255 | O1: 255 | P1: 255 | Q1: 255 | R1: 255 | S1: 255 | T1: 255 | U1: 255 | V1: 255 | W1: 255 | X1: 255 | Y1: 255 | Z1: 255 | AA1: 255 | AB1: 255 | AC1: 255 | AD1: 255
A2: 255 | B2: 255 | C2: 255 | D2: 255 | E2: 255 | F2: 255 | G2: 255 | H2: 255 | I2: 255 | J2: 255 | K2: 255 | L2: 255 | M2: 255 | N2: 255 | O2: 255 | P2: 255 | Q2: 255 | R2: 255 | S2: 255 | T2: 255 | U2: 255 | V2: 255 | W2: 255 | X2: 255 | Y2: 255 | Z2: 255 | AA2: 255 | AB2: 255 | AC2: 255 | AD2: 255
A3: 255 | B3: 255 | C3: 255 | D3: 255 | E3: 255 | F3: 255 | G3: 255 | H3: 255 | I3: 255 | J3: 255 | K3: 255 | L3: 255 | M3: 255 | N3: 255 | O3: 255 | P3: 255 | Q3: 255 | R3: 255 | S3: 255 | T3: 255 | U3: 255 | V3: 255 | W3: 255 | X3: 255 | Y3: 255 | Z3: 255 | AA3: 255 | AB3: 255 | AC3: 255 | AD3: 255
A4: 255 | B4: 255 | C4: 255 | D4: 255 | E4: 255 | F4: 255 | G4: 255 | H4: 255 | I4: 255 | J4: 255 | K4: 255 | L4: 255 | M4: 255 | N4: 255 | O4: 255 | P4: 255 | Q4: 255 | R4: 255 | S4: 255 | T4: 255 | U4: 255 | V4: 255 | W4: 255 | X4: 255 | Y4: 255 | Z4: 255 | AA4: 255 | AB4: 255 | AC4: 255 | AD4: 255
A5: 255 | B5: 255 | C5: 255 | D5: 255 | E5: 255 | F5: 255 | G5: 255 | H5: 255 | I5: 255 | J5: 255 | K5: 255 | L5: 255 | M5: 255 | N5: 255 | O5: 255 | P5: 255 | Q5: 255 | R5: 255 | S5: 255 | T5: 255 | U5: 255 | V5: 255 | W5: 255 | X5: 255 | Y5: 255 | Z5: 255 | AA5: 255 | AB5: 255 | AC5: 255 | AD5: 255
A6: 255 | B6: 255 | C6: 255 | D6: 255 | E6: 255 | F6: 255 | G6: 255 | H6: 255 | I6: 0 | J6: 0 | K6: 0 | L6: 0 | M6: 0 | N6: 255 | O6: 255 | P6: 255 | Q6: 255 | R6: 0 | S6: 0 | T6: 0 | U6: 0 | V6: 0 | W6: 255 | X6: 255 | Y6: 255 | Z6: 255 | AA6: 255 | AB6: 255 | AC6: 255 | AD6: 255
A7: 255 | B7: 255 | C7: 255 | D7: 255 | E7: 255 | F7: 255 | G7: 255 | H7: 0 | I7: 0 | J7: 0 | K7: 0 | L7: 0 | M7: 0 | N7: 0 | O7: 255 | P7: 255 | Q7: 0 | R7: 0 | S7: 0 | T7: 0 | U7: 0 | V7: 0 | W7: 0 | X7: 255 | Y7: 255 | Z7: 255 | AA7: 255 | AB7: 255 | AC7: 255 | AD7: 255
A8: 255 | B8: 255 | C8: 255 | D8: 255 | E8: 255 | F8: 255 | G8: 0 | H8: 0 | I8: 0 | J8: 0 | K8: 0 | L8: 0 | M8: 0 | N8: 0 | O8: 0 | P8: 0 | Q8: 0 | R8: 0 | S8: 0 | T8: 0 | U8: 0 | V8: 0 | W8: 0 | X8: 0 | Y8: 255 | Z8: 255 | AA8: 255 | AB8: 255 | AC8: 255 | AD8: 255
A9: 255 | B9: 255 | C9: 255 | D9: 255 | E9: 255 | F9: 0 | G9: 0 | H9: 0 | I9: 0 | J9: 0 | K9: 0 | L9: 0 | M9: 0 | N9: 0 | O9: 0 | P9: 0 | Q9: 0 | R9: 0 | S9: 0 | T9: 0 | U9: 0 | V9: 0 | W9: 0 | X9: 0 | Y9: 0 | Z9: 255 | AA9: 255 | AB9: 255 | AC9: 255 | AD9: 255
A10: 255 | B10: 255 | C10: 255 | D10: 255 | E10: 255 | F10: 0 | G10: 0 | H10: 0 | I10: 0 | J10: 0 | K10: 0 | L10: 0 | M10: 0 | N10: 0 | O10: 0 | P10: 0 | Q10: 0 | R10: 0 | S10: 0 | T10: 0 | U10: 0 | V10: 0 | W10: 0 | X10: 0 | Y10: 0 | Z10: 255 | AA10: 255 | AB10: 255 | AC10: 255 | AD10: 255
A11: 255 | B11: 255 | C11: 255 | D11: 255 | E11: 255 | F11: 255 | G11: 0 | H11: 0 | I11: 0 | J11: 0 | K11: 0 | L11: 0 | M11: 0 | N11: 0 | O11: 0 | P11: 0 | Q11: 0 | R11: 0 | S11: 0 | T11: 0 | U11: 0 | V11: 0 | W11: 0 | X11: 0 | Y11: 255 | Z11: 255 | AA11: 255 | AB11: 255 | AC11: 255 | AD11: 255
A12: 255 | B12: 255 | C12: 255 | D12: 255 | E12: 255 | F12: 255 | G12: 255 | H12: 0 | I12: 0 | J12: 0 | K12: 0 | L12: 0 | M12: 0 | N12: 0 | O12: 0 | P12: 0 | Q12: 0 | R12: 0 | S12: 0 | T12: 0 | U12: 0 | V12: 0 | W12: 0 | X12: 255 | Y12: 255 | Z12: 255 | AA12: 255 | AB12: 255 | AC12: 255 | AD12: 255
... A30: 255 | B30: 255 | C30: 255 | D30: 255 | E30: 255 | F30: 255 | G30: 255 | H30: 255 | I30: 255 | J30: 255 | K30: 255 | L30: 255 | M30: 255 | N30: 255 | O30: 255 | P30: 255 | Q30: 255 | R30: 255 | S30: 255 | T30: 255 | U30: 255 | V30: 255 | W30: 255 | X30: 255 | Y30: 255 | Z30: 255 | AA30: 255 | AB30: 255 | AC30: 255 | AD30: 255
A32: 0

Sheet Convoluciones
A1: =SUMPRODUCT(Imagen_Original!A1:C3,$AF$2:$AH$4) -> 255 | B1: =SUMPRODUCT(Imagen_Original!B1:D3,$AF$2:$AH$4) -> 255 | C1: =SUMPRODUCT(Imagen_Original!C1:E3,$AF$2:$AH$4) -> 255 | D1: =SUMPRODUCT(Imagen_Original!D1:F3,$AF$2:$AH$4) -> 255 | E1: =SUMPRODUCT(Imagen_Original!E1:G3,$AF$2:$AH$4) -> 255 | F1: =SUMPRODUCT(Imagen_Original!F1:H3,$AF$2:$AH$4) -> 255 | G1: =SUMPRODUCT(Imagen_Original!G1:I3,$AF$2:$AH$4) -> 255 | H1: =SUMPRODUCT(Imagen_Original!H1:J3,$AF$2:$AH$4) -> 255 | ... AB1: =SUMPRODUCT(Imagen_Original!AB1:AD3,$AF$2:$AH$4) -> 255
A2: =SUMPRODUCT(Imagen_Original!A2:C4,$AF$2:$AH$4) -> 255 | B2: =SUMPRODUCT(Imagen_Original!B2:D4,$AF$2:$AH$4) -> 255 | C2: =SUMPRODUCT(Imagen_Original!C2:E4,$AF$2:$AH$4) -> 255 | D2: =SUMPRODUCT(Imagen_Original!D2:F4,$AF$2:$AH$4) -> 255 | E2: =SUMPRODUCT(Imagen_Original!E2:G4,$AF$2:$AH$4) -> 255 | F2: =SUMPRODUCT(Imagen_Original!F2:H4,$AF$2:$AH$4) -> 255 | G2: =SUMPRODUCT(Imagen_Original!G2:I4,$AF$2:$AH$4) -> 255 | H2: =SUMPRODUCT(Imagen_Original!H2:J4,$AF$2:$AH$4) -> 255 | ... AB2: =SUMPRODUCT(Imagen_Original!AB2:AD4,$AF$2:$AH$4) -> 255 | AF2: 0 | AG2: 0 | AH2: 0 | AJ2: -1 | AK2: -1 | AL2: -1 | AN2: 46266 | AO2: 46266 | AP2: 46266 | AR2: 0 | AS2: -1 | AT2: 0
A3: =SUMPRODUCT(Imagen_Original!A3:C5,$AF$2:$AH$4) -> 255 | B3: =SUMPRODUCT(Imagen_Original!B3:D5,$AF$2:$AH$4) -> 255 | C3: =SUMPRODUCT(Imagen_Original!C3:E5,$AF$2:$AH$4) -> 255 | D3: =SUMPRODUCT(Imagen_Original!D3:F5,$AF$2:$AH$4) -> 255 | E3: =SUMPRODUCT(Imagen_Original!E3:G5,$AF$2:$AH$4) -> 255 | F3: =SUMPRODUCT(Imagen_Original!F3:H5,$AF$2:$AH$4) -> 255 | G3: =SUMPRODUCT(Imagen_Original!G3:I5,$AF$2:$AH$4) -> 255 | H3: =SUMPRODUCT(Imagen_Original!H3:J5,$AF$2:$AH$4) -> 255 | ... AB3: =SUMPRODUCT(Imagen_Original!AB3:AD5,$AF$2:$AH$4) -> 255 | AF3: 0 | AG3: 1 | AH3: 0 | AJ3: -1 | AK3: 8 | AL3: -1 | AN3: 46266 | AO3: 46266 | AP3: 46266 | AR3: -1 | AS3: 5 | AT3: -1
A4: =SUMPRODUCT(Imagen_Original!A4:C6,$AF$2:$AH$4) -> 255 | B4: =SUMPRODUCT(Imagen_Original!B4:D6,$AF$2:$AH$4) -> 255 | C4: =SUMPRODUCT(Imagen_Original!C4:E6,$AF$2:$AH$4) -> 255 | D4: =SUMPRODUCT(Imagen_Original!D4:F6,$AF$2:$AH$4) -> 255 | E4: =SUMPRODUCT(Imagen_Original!E4:G6,$AF$2:$AH$4) -> 255 | F4: =SUMPRODUCT(Imagen_Original!F4:H6,$AF$2:$AH$4) -> 255 | G4: =SUMPRODUCT(Imagen_Original!G4:I6,$AF$2:$AH$4) -> 255 | H4: =SUMPRODUCT(Imagen_Original!H4:J6,$AF$2:$AH$4) -> 255 | ... AB4: =SUMPRODUCT(Imagen_Original!AB4:AD6,$AF$2:$AH$4) -> 255 | AF4: 0 | AG4: 0 | AH4: 0 | AJ4: -1 | AK4: -1 | AL4: -1 | AN4: 46266 | AO4: 46266 | AP4: 46266 | AR4: 0 | AS4: -1 | AT4: 0
A5: =SUMPRODUCT(Imagen_Original!A5:C7,$AF$2:$AH$4) -> 255 | B5: =SUMPRODUCT(Imagen_Original!B5:D7,$AF$2:$AH$4) -> 255 | C5: =SUMPRODUCT(Imagen_Original!C5:E7,$AF$2:$AH$4) -> 255 | D5: =SUMPRODUCT(Imagen_Original!D5:F7,$AF$2:$AH$4) -> 255 | E5: =SUMPRODUCT(Imagen_Original!E5:G7,$AF$2:$AH$4) -> 255 | F5: =SUMPRODUCT(Imagen_Original!F5:H7,$AF$2:$AH$4) -> 255 | G5: =SUMPRODUCT(Imagen_Original!G5:I7,$AF$2:$AH$4) -> 255 | H5: =SUMPRODUCT(Imagen_Original!H5:J7,$AF$2:$AH$4) -> 0 | ... AB5: =SUMPRODUCT(Imagen_Original!AB5:AD7,$AF$2:$AH$4) -> 255
A6: =SUMPRODUCT(Imagen_Original!A6:C8,$AF$2:$AH$4) -> 255 | B6: =SUMPRODUCT(Imagen_Original!B6:D8,$AF$2:$AH$4) -> 255 | C6: =SUMPRODUCT(Imagen_Original!C6:E8,$AF$2:$AH$4) -> 255 | D6: =SUMPRODUCT(Imagen_Original!D6:F8,$AF$2:$AH$4) -> 255 | E6: =SUMPRODUCT(Imagen_Original!E6:G8,$AF$2:$AH$4) -> 255 | F6: =SUMPRODUCT(Imagen_Original!F6:H8,$AF$2:$AH$4) -> 255 | G6: =SUMPRODUCT(Imagen_Original!G6:I8,$AF$2:$AH$4) -> 0 | H6: =SUMPRODUCT(Imagen_Original!H6:J8,$AF$2:$AH$4) -> 0 | ... AB6: =SUMPRODUCT(Imagen_Original!AB6:AD8,$AF$2:$AH$4) -> 255
A7: =SUMPRODUCT(Imagen_Original!A7:C9,$AF$2:$AH$4) -> 255 | B7: =SUMPRODUCT(Imagen_Original!B7:D9,$AF$2:$AH$4) -> 255 | C7: =SUMPRODUCT(Imagen_Original!C7:E9,$AF$2:$AH$4) -> 255 | D7: =SUMPRODUCT(Imagen_Original!D7:F9,$AF$2:$AH$4) -> 255 | E7: =SUMPRODUCT(Imagen_Original!E7:G9,$AF$2:$AH$4) -> 255 | F7: =SUMPRODUCT(Imagen_Original!F7:H9,$AF$2:$AH$4) -> 0 | G7: =SUMPRODUCT(Imagen_Original!G7:I9,$AF$2:$AH$4) -> 0 | H7: =SUMPRODUCT(Imagen_Original!H7:J9,$AF$2:$AH$4) -> 0 | ... AB7: =SUMPRODUCT(Imagen_Original!AB7:AD9,$AF$2:$AH$4) -> 255
A8: =SUMPRODUCT(Imagen_Original!A8:C10,$AF$2:$AH$4) -> 255 | B8: =SUMPRODUCT(Imagen_Original!B8:D10,$AF$2:$AH$4) -> 255 | C8: =SUMPRODUCT(Imagen_Original!C8:E10,$AF$2:$AH$4) -> 255 | D8: =SUMPRODUCT(Imagen_Original!D8:F10,$AF$2:$AH$4) -> 255 | E8: =SUMPRODUCT(Imagen_Original!E8:G10,$AF$2:$AH$4) -> 0 | F8: =SUMPRODUCT(Imagen_Original!F8:H10,$AF$2:$AH$4) -> 0 | G8: =SUMPRODUCT(Imagen_Original!G8:I10,$AF$2:$AH$4) -> 0 | H8: =SUMPRODUCT(Imagen_Original!H8:J10,$AF$2:$AH$4) -> 0 | ... AB8: =SUMPRODUCT(Imagen_Original!AB8:AD10,$AF$2:$AH$4) -> 255
A9: =SUMPRODUCT(Imagen_Original!A9:C11,$AF$2:$AH$4) -> 255 | B9: =SUMPRODUCT(Imagen_Original!B9:D11,$AF$2:$AH$4) -> 255 | C9: =SUMPRODUCT(Imagen_Original!C9:E11,$AF$2:$AH$4) -> 255 | D9: =SUMPRODUCT(Imagen_Original!D9:F11,$AF$2:$AH$4) -> 255 | E9: =SUMPRODUCT(Imagen_Original!E9:G11,$AF$2:$AH$4) -> 0 | F9: =SUMPRODUCT(Imagen_Original!F9:H11,$AF$2:$AH$4) -> 0 | G9: =SUMPRODUCT(Imagen_Original!G9:I11,$AF$2:$AH$4) -> 0 | H9: =SUMPRODUCT(Imagen_Original!H9:J11,$AF$2:$AH$4) -> 0 | ... AB9: =SUMPRODUCT(Imagen_Original!AB9:AD11,$AF$2:$AH$4) -> 255
A10: =SUMPRODUCT(Imagen_Original!A10:C12,$AF$2:$AH$4) -> 255 | B10: =SUMPRODUCT(Imagen_Original!B10:D12,$AF$2:$AH$4) -> 255 | C10: =SUMPRODUCT(Imagen_Original!C10:E12,$AF$2:$AH$4) -> 255 | D10: =SUMPRODUCT(Imagen_Original!D10:F12,$AF$2:$AH$4) -> 255 | E10: =SUMPRODUCT(Imagen_Original!E10:G12,$AF$2:$AH$4) -> 255 | F10: =SUMPRODUCT(Imagen_Original!F10:H12,$AF$2:$AH$4) -> 0 | G10: =SUMPRODUCT(Imagen_Original!G10:I12,$AF$2:$AH$4) -> 0 | H10: =SUMPRODUCT(Imagen_Original!H10:J12,$AF$2:$AH$4) -> 0 | ... AB10: =SUMPRODUCT(Imagen_Original!AB10:AD12,$AF$2:$AH$4) -> 255
A11: =SUMPRODUCT(Imagen_Original!A11:C13,$AF$2:$AH$4) -> 255 | B11: =SUMPRODUCT(Imagen_Original!B11:D13,$AF$2:$AH$4) -> 255 | C11: =SUMPRODUCT(Imagen_Original!C11:E13,$AF$2:$AH$4) -> 255 | D11: =SUMPRODUCT(Imagen_Original!D11:F13,$AF$2:$AH$4) -> 255 | E11: =SUMPRODUCT(Imagen_Original!E11:G13,$AF$2:$AH$4) -> 255 | F11: =SUMPRODUCT(Imagen_Original!F11:H13,$AF$2:$AH$4) -> 255 | G11: =SUMPRODUCT(Imagen_Original!G11:I13,$AF$2:$AH$4) -> 0 | H11: =SUMPRODUCT(Imagen_Original!H11:J13,$AF$2:$AH$4) -> 0 | ... AB11: =SUMPRODUCT(Imagen_Original!AB11:AD13,$AF$2:$AH$4) -> 255
A12: =SUMPRODUCT(Imagen_Original!A12:C14,$AF$2:$AH$4) -> 255 | B12: =SUMPRODUCT(Imagen_Original!B12:D14,$AF$2:$AH$4) -> 255 | C12: =SUMPRODUCT(Imagen_Original!C12:E14,$AF$2:$AH$4) -> 255 | D12: =SUMPRODUCT(Imagen_Original!D12:F14,$AF$2:$AH$4) -> 255 | E12: =SUMPRODUCT(Imagen_Original!E12:G14,$AF$2:$AH$4) -> 255 | F12: =SUMPRODUCT(Imagen_Original!F12:H14,$AF$2:$AH$4) -> 255 | G12: =SUMPRODUCT(Imagen_Original!G12:I14,$AF$2:$AH$4) -> 255 | H12: =SUMPRODUCT(Imagen_Original!H12:J14,$AF$2:$AH$4) -> 0 | ... AB12: =SUMPRODUCT(Imagen_Original!AB12:AD14,$AF$2:$AH$4) -> 255
A13: =SUMPRODUCT(Imagen_Original!A13:C15,$AF$2:$AH$4) -> 255 | B13: =SUMPRODUCT(Imagen_Original!B13:D15,$AF$2:$AH$4) -> 255 | C13: =SUMPRODUCT(Imagen_Original!C13:E15,$AF$2:$AH$4) -> 255 | D13: =SUMPRODUCT(Imagen_Original!D13:F15,$AF$2:$AH$4) -> 255 | E13: =SUMPRODUCT(Imagen_Original!E13:G15,$AF$2:$AH$4) -> 255 | F13: =SUMPRODUCT(Imagen_Original!F13:H15,$AF$2:$AH$4) -> 255 | G13: =SUMPRODUCT(Imagen_Original!G13:I15,$AF$2:$AH$4) -> 255 | H13: =SUMPRODUCT(Imagen_Original!H13:J15,$AF$2:$AH$4) -> 255 | ... AB13: =SUMPRODUCT(Imagen_Original!AB13:AD15,$AF$2:$AH$4) -> 255
A14: =SUMPRODUCT(Imagen_Original!A14:C16,$AF$2:$AH$4) -> 255 | B14: =SUMPRODUCT(Imagen_Original!B14:D16,$AF$2:$AH$4) -> 255 | C14: =SUMPRODUCT(Imagen_Original!C14:E16,$AF$2:$AH$4) -> 255 | D14: =SUMPRODUCT(Imagen_Original!D14:F16,$AF$2:$AH$4) -> 255 | E14: =SUMPRODUCT(Imagen_Original!E14:G16,$AF$2:$AH$4) -> 255 | F14: =SUMPRODUCT(Imagen_Original!F14:H16,$AF$2:$AH$4) -> 255 | G14: =SUMPRODUCT(Imagen_Original!G14:I16,$AF$2:$AH$4) -> 255 | H14: =SUMPRODUCT(Imagen_Original!H14:J16,$AF$2:$AH$4) -> 255 | ... AB14: =SUMPRODUCT(Imagen_Original!AB14:AD16,$AF$2:$AH$4) -> 255
A15: =SUMPRODUCT(Imagen_Original!A15:C17,$AF$2:$AH$4) -> 255 | B15: =SUMPRODUCT(Imagen_Original!B15:D17,$AF$2:$AH$4) -> 255 | C15: =SUMPRODUCT(Imagen_Original!C15:E17,$AF$2:$AH$4) -> 255 | D15: =SUMPRODUCT(Imagen_Original!D15:F17,$AF$2:$AH$4) -> 255 | E15: =SUMPRODUCT(Imagen_Original!E15:G17,$AF$2:$AH$4) -> 255 | F15: =SUMPRODUCT(Imagen_Original!F15:H17,$AF$2:$AH$4) -> 255 | G15: =SUMPRODUCT(Imagen_Original!G15:I17,$AF$2:$AH$4) -> 255 | H15: =SUMPRODUCT(Imagen_Original!H15:J17,$AF$2:$AH$4) -> 255 | ... AB15: =SUMPRODUCT(Imagen_Original!AB15:AD17,$AF$2:$AH$4) -> 255
A16: =SUMPRODUCT(Imagen_Original!A16:C18,$AF$2:$AH$4) -> 255 | B16: =SUMPRODUCT(Imagen_Original!B16:D18,$AF$2:$AH$4) -> 255 | C16: =SUMPRODUCT(Imagen_Original!C16:E18,$AF$2:$AH$4) -> 255 | D16: =SUMPRODUCT(Imagen_Original!D16:F18,$AF$2:$AH$4) -> 255 | E16: =SUMPRODUCT(Imagen_Original!E16:G18,$AF$2:$AH$4) -> 255 | F16: =SUMPRODUCT(Imagen_Original!F16:H18,$AF$2:$AH$4) -> 255 | G16: =SUMPRODUCT(Imagen_Original!G16:I18,$AF$2:$AH$4) -> 255 | H16: =SUMPRODUCT(Imagen_Original!H16:J18,$AF$2:$AH$4) -> 255 | ... AB16: =SUMPRODUCT(Imagen_Original!AB16:AD18,$AF$2:$AH$4) -> 255
... A28: =SUMPRODUCT(Imagen_Original!A28:C30,$AF$2:$AH$4) -> 255 | B28: =SUMPRODUCT(Imagen_Original!B28:D30,$AF$2:$AH$4) -> 255 | C28: =SUMPRODUCT(Imagen_Original!C28:E30,$AF$2:$AH$4) -> 255 | D28: =SUMPRODUCT(Imagen_Original!D28:F30,$AF$2:$AH$4) -> 255 | E28: =SUMPRODUCT(Imagen_Original!E28:G30,$AF$2:$AH$4) -> 255 | F28: =SUMPRODUCT(Imagen_Original!F28:H30,$AF$2:$AH$4) -> 255 | G28: =SUMPRODUCT(Imagen_Original!G28:I30,$AF$2:$AH$4) -> 255 | H28: =SUMPRODUCT(Imagen_Original!H28:J30,$AF$2:$AH$4) -> 255 | ... AB28: =SUMPRODUCT(Imagen_Original!AB28:AD30,$AF$2:$AH$4) -> 255
A32: =SUMPRODUCT(Imagen_Original!A1:C3,$AJ$2:$AL$4) -> 0 | B32: =SUMPRODUCT(Imagen_Original!B1:D3,$AJ$2:$AL$4) -> 0 | C32: =SUMPRODUCT(Imagen_Original!C1:E3,$AJ$2:$AL$4) -> 0 | D32: =SUMPRODUCT(Imagen_Original!D1:F3,$AJ$2:$AL$4) -> 0 | E32: =SUMPRODUCT(Imagen_Original!E1:G3,$AJ$2:$AL$4) -> 0 | F32: =SUMPRODUCT(Imagen_Original!F1:H3,$AJ$2:$AL$4) -> 0 | G32: =SUMPRODUCT(Imagen_Original!G1:I3,$AJ$2:$AL$4) -> 0 | H32: =SUMPRODUCT(Imagen_Original!H1:J3,$AJ$2:$AL$4) -> 0 | ... AB32: =SUMPRODUCT(Imagen_Original!AB1:AD3,$AJ$2:$AL$4) -> 0
A33: =SUMPRODUCT(Imagen_Original!A2:C4,$AJ$2:$AL$4) -> 0 | B33: =SUMPRODUCT(Imagen_Original!B2:D4,$AJ$2:$AL$4) -> 0 | C33: =SUMPRODUCT(Imagen_Original!C2:E4,$AJ$2:$AL$4) -> 0 | D33: =SUMPRODUCT(Imagen_Original!D2:F4,$AJ$2:$AL$4) -> 0 | E33: =SUMPRODUCT(Imagen_Original!E2:G4,$AJ$2:$AL$4) -> 0 | F33: =SUMPRODUCT(Imagen_Original!F2:H4,$AJ$2:$AL$4) -> 0 | G33: =SUMPRODUCT(Imagen_Original!G2:I4,$AJ$2:$AL$4) -> 0 | H33: =SUMPRODUCT(Imagen_Original!H2:J4,$AJ$2:$AL$4) -> 0 | ... AB33: =SUMPRODUCT(Imagen_Original!AB2:AD4,$AJ$2:$AL$4) -> 0
A34: =SUMPRODUCT(Imagen_Original!A3:C5,$AJ$2:$AL$4) -> 0 | B34: =SUMPRODUCT(Imagen_Original!B3:D5,$AJ$2:$AL$4) -> 0 | C34: =SUMPRODUCT(Imagen_Original!C3:E5,$AJ$2:$AL$4) -> 0 | D34: =SUMPRODUCT(Imagen_Original!D3:F5,$AJ$2:$AL$4) -> 0 | E34: =SUMPRODUCT(Imagen_Original!E3:G5,$AJ$2:$AL$4) -> 0 | F34: =SUMPRODUCT(Imagen_Original!F3:H5,$AJ$2:$AL$4) -> 0 | G34: =SUMPRODUCT(Imagen_Original!G3:I5,$AJ$2:$AL$4) -> 0 | H34: =SUMPRODUCT(Imagen_Original!H3:J5,$AJ$2:$AL$4) -> 0 | ... AB34: =SUMPRODUCT(Imagen_Original!AB3:AD5,$AJ$2:$AL$4) -> 0
A35: =SUMPRODUCT(Imagen_Original!A4:C6,$AJ$2:$AL$4) -> 0 | B35: =SUMPRODUCT(Imagen_Original!B4:D6,$AJ$2:$AL$4) -> 0 | C35: =SUMPRODUCT(Imagen_Original!C4:E6,$AJ$2:$AL$4) -> 0 | D35: =SUMPRODUCT(Imagen_Original!D4:F6,$AJ$2:$AL$4) -> 0 | E35: =SUMPRODUCT(Imagen_Original!E4:G6,$AJ$2:$AL$4) -> 0 | F35: =SUMPRODUCT(Imagen_Original!F4:H6,$AJ$2:$AL$4) -> 0 | G35: =SUMPRODUCT(Imagen_Original!G4:I6,$AJ$2:$AL$4) -> 255 | H35: =SUMPRODUCT(Imagen_Original!H4:J6,$AJ$2:$AL$4) -> 510 | ... AB35: =SUMPRODUCT(Imagen_Original!AB4:AD6,$AJ$2:$AL$4) -> 0
A36: =SUMPRODUCT(Imagen_Original!A5:C7,$AJ$2:$AL$4) -> 0 | B36: =SUMPRODUCT(Imagen_Original!B5:D7,$AJ$2:$AL$4) -> 0 | C36: =SUMPRODUCT(Imagen_Original!C5:E7,$AJ$2:$AL$4) -> 0 | D36: =SUMPRODUCT(Imagen_Original!D5:F7,$AJ$2:$AL$4) -> 0 | E36: =SUMPRODUCT(Imagen_Original!E5:G7,$AJ$2:$AL$4) -> 0 | F36: =SUMPRODUCT(Imagen_Original!F5:H7,$AJ$2:$AL$4) -> 255 | G36: =SUMPRODUCT(Imagen_Original!G5:I7,$AJ$2:$AL$4) -> 765 | H36: =SUMPRODUCT(Imagen_Original!H5:J7,$AJ$2:$AL$4) -> -1020 | ... AB36: =SUMPRODUCT(Imagen_Original!AB5:AD7,$AJ$2:$AL$4) -> 0
A37: =SUMPRODUCT(Imagen_Original!A6:C8,$AJ$2:$AL$4) -> 0 | B37: =SUMPRODUCT(Imagen_Original!B6:D8,$AJ$2:$AL$4) -> 0 | C37: =SUMPRODUCT(Imagen_Original!C6:E8,$AJ$2:$AL$4) -> 0 | D37: =SUMPRODUCT(Imagen_Original!D6:F8,$AJ$2:$AL$4) -> 0 | E37: =SUMPRODUCT(Imagen_Original!E6:G8,$AJ$2:$AL$4) -> 255 | F37: =SUMPRODUCT(Imagen_Original!F6:H8,$AJ$2:$AL$4) -> 765 | G37: =SUMPRODUCT(Imagen_Original!G6:I8,$AJ$2:$AL$4) -> -765 | H37: =SUMPRODUCT(Imagen_Original!H6:J8,$AJ$2:$AL$4) -> -255 | ... AB37: =SUMPRODUCT(Imagen_Original!AB6:AD8,$AJ$2:$AL$4) -> 0
A38: =SUMPRODUCT(Imagen_Original!A7:C9,$AJ$2:$AL$4) -> 0 | B38: =SUMPRODUCT(Imagen_Original!B7:D9,$AJ$2:$AL$4) -> 0 | C38: =SUMPRODUCT(Imagen_Original!C7:E9,$AJ$2:$AL$4) -> 0 | D38: =SUMPRODUCT(Imagen_Original!D7:F9,$AJ$2:$AL$4) -> 255 | E38: =SUMPRODUCT(Imagen_Original!E7:G9,$AJ$2:$AL$4) -> 765 | F38: =SUMPRODUCT(Imagen_Original!F7:H9,$AJ$2:$AL$4) -> -765 | G38: =SUMPRODUCT(Imagen_Original!G7:I9,$AJ$2:$AL$4) -> -255 | H38: =SUMPRODUCT(Imagen_Original!H7:J9,$AJ$2:$AL$4) -> 0 | ... AB38: =SUMPRODUCT(Imagen_Original!AB7:AD9,$AJ$2:$AL$4) -> 0
A39: =SUMPRODUCT(Imagen_Original!A8:C10,$AJ$2:$AL$4) -> 0 | B39: =SUMPRODUCT(Imagen_Original!B8:D10,$AJ$2:$AL$4) -> 0 | C39: =SUMPRODUCT(Imagen_Original!C8:E10,$AJ$2:$AL$4) -> 0 | D39: =SUMPRODUCT(Imagen_Original!D8:F10,$AJ$2:$AL$4) -> 510 | E39: =SUMPRODUCT(Imagen_Original!E8:G10,$AJ$2:$AL$4) -> -1020 | F39: =SUMPRODUCT(Imagen_Original!F8:H10,$AJ$2:$AL$4) -> -255 | G39: =SUMPRODUCT(Imagen_Original!G8:I10,$AJ$2:$AL$4) -> 0 | H39: =SUMPRODUCT(Imagen_Original!H8:J10,$AJ$2:$AL$4) -> 0 | ... AB39: =SUMPRODUCT(Imagen_Original!AB8:AD10,$AJ$2:$AL$4) -> 0
A40: =SUMPRODUCT(Imagen_Original!A9:C11,$AJ$2:$AL$4) -> 0 | B40: =SUMPRODUCT(Imagen_Original!B9:D11,$AJ$2:$AL$4) -> 0 | C40: =SUMPRODUCT(Imagen_Original!C9:E11,$AJ$2:$AL$4) -> 0 | D40: =SUMPRODUCT(Imagen_Original!D9:F11,$AJ$2:$AL$4) -> 510 | E40: =SUMPRODUCT(Imagen_Original!E9:G11,$AJ$2:$AL$4) -> -1020 | F40: =SUMPRODUCT(Imagen_Original!F9:H11,$AJ$2:$AL$4) -> -255 | G40: =SUMPRODUCT(Imagen_Original!G9:I11,$AJ$2:$AL$4) -> 0 | H40: =SUMPRODUCT(Imagen_Original!H9:J11,$AJ$2:$AL$4) -> 0 | ... AB40: =SUMPRODUCT(Imagen_Original!AB9:AD11,$AJ$2:$AL$4) -> 0
A41: =SUMPRODUCT(Imagen_Original!A10:C12,$AJ$2:$AL$4) -> 0 | B41: =SUMPRODUCT(Imagen_Original!B10:D12,$AJ$2:$AL$4) -> 0 | C41: =SUMPRODUCT(Imagen_Original!C10:E12,$AJ$2:$AL$4) -> 0 | D41: =SUMPRODUCT(Imagen_Original!D10:F12,$AJ$2:$AL$4) -> 255 | E41: =SUMPRODUCT(Imagen_Original!E10:G12,$AJ$2:$AL$4) -> 765 | F41: =SUMPRODUCT(Imagen_Original!F10:H12,$AJ$2:$AL$4) -> -765 | G41: =SUMPRODUCT(Imagen_Original!G10:I12,$AJ$2:$AL$4) -> -255 | H41: =SUMPRODUCT(Imagen_Original!H10:J12,$AJ$2:$AL$4) -> 0 | ... AB41: =SUMPRODUCT(Imagen_Original!AB10:AD12,$AJ$2:$AL$4) -> 0
A42: =SUMPRODUCT(Imagen_Original!A11:C13,$AJ$2:$AL$4) -> 0 | B42: =SUMPRODUCT(Imagen_Original!B11:D13,$AJ$2:$AL$4) -> 0 | C42: =SUMPRODUCT(Imagen_Original!C11:E13,$AJ$2:$AL$4) -> 0 | D42: =SUMPRODUCT(Imagen_Original!D11:F13,$AJ$2:$AL$4) -> 0 | E42: =SUMPRODUCT(Imagen_Original!E11:G13,$AJ$2:$AL$4) -> 255 | F42: =SUMPRODUCT(Imagen_Original!F11:H13,$AJ$2:$AL$4) -> 765 | G42: =SUMPRODUCT(Imagen_Original!G11:I13,$AJ$2:$AL$4) -> -765 | H42: =SUMPRODUCT(Imagen_Original!H11:J13,$AJ$2:$AL$4) -> -255 | ... AB42: =SUMPRODUCT(Imagen_Original!AB11:AD13,$AJ$2:$AL$4) -> 0
A43: =SUMPRODUCT(Imagen_Original!A12:C14,$AJ$2:$AL$4) -> 0 | B43: =SUMPRODUCT(Imagen_Original!B12:D14,$AJ$2:$AL$4) -> 0 | C43: =SUMPRODUCT(Imagen_Original!C12:E14,$AJ$2:$AL$4) -> 0 | D43: =SUMPRODUCT(Imagen_Original!D12:F14,$AJ$2:$AL$4) -> 0 | E43: =SUMPRODUCT(Imagen_Original!E12:G14,$AJ$2:$AL$4) -> 0 | F43: =SUMPRODUCT(Imagen_Original!F12:H14,$AJ$2:$AL$4) -> 255 | G43: =SUMPRODUCT(Imagen_Original!G12:I14,$AJ$2:$AL$4) -> 765 | H43: =SUMPRODUCT(Imagen_Original!H12:J14,$AJ$2:$AL$4) -> -765 | ... AB43: =SUMPRODUCT(Imagen_Original!AB12:AD14,$AJ$2:$AL$4) -> 0
... A59: =SUMPRODUCT(Imagen_Original!A28:C30,$AJ$2:$AL$4) -> 0 | B59: =SUMPRODUCT(Imagen_Original!B28:D30,$AJ$2:$AL$4) -> 0 | C59: =SUMPRODUCT(Imagen_Original!C28:E30,$AJ$2:$AL$4) -> 0 | D59: =SUMPRODUCT(Imagen_Original!D28:F30,$AJ$2:$AL$4) -> 0 | E59: =SUMPRODUCT(Imagen_Original!E28:G30,$AJ$2:$AL$4) -> 0 | F59: =SUMPRODUCT(Imagen_Original!F28:H30,$AJ$2:$AL$4) -> 0 | G59: =SUMPRODUCT(Imagen_Original!G28:I30,$AJ$2:$AL$4) -> 0 | H59: =SUMPRODUCT(Imagen_Original!H28:J30,$AJ$2:$AL$4) -> 0 | ... AB59: =SUMPRODUCT(Imagen_Original!AB28:AD30,$AJ$2:$AL$4) -> 0
A62: =MIN(255,ABS(A32)) -> 0 | B62: =MIN(255,ABS(B32)) -> 0 | C62: =MIN(255,ABS(C32)) -> 0 | D62: =MIN(255,ABS(D32)) -> 0 | E62: =MIN(255,ABS(E32)) -> 0 | F62: =MIN(255,ABS(F32)) -> 0 | G62: =MIN(255,ABS(G32)) -> 0 | H62: =MIN(255,ABS(H32)) -> 0 | ... AB62: =MIN(255,ABS(AB32)) -> 0
A63: =MIN(255,ABS(A33)) -> 0 | B63: =MIN(255,ABS(B33)) -> 0 | C63: =MIN(255,ABS(C33)) -> 0 | D63: =MIN(255,ABS(D33)) -> 0 | E63: =MIN(255,ABS(E33)) -> 0 | F63: =MIN(255,ABS(F33)) -> 0 | G63: =MIN(255,ABS(G33)) -> 0 | H63: =MIN(255,ABS(H33)) -> 0 | ... AB63: =MIN(255,ABS(AB33)) -> 0
A64: =MIN(255,ABS(A34)) -> 0 | B64: =MIN(255,ABS(B34)) -> 0 | C64: =MIN(255,ABS(C34)) -> 0 | D64: =MIN(255,ABS(D34)) -> 0 | E64: =MIN(255,ABS(E34)) -> 0 | F64: =MIN(255,ABS(F34)) -> 0 | G64: =MIN(255,ABS(G34)) -> 0 | H64: =MIN(255,ABS(H34)) -> 0 | ... AB64: =MIN(255,ABS(AB34)) -> 0
A65: =MIN(255,ABS(A35)) -> 0 | B65: =MIN(255,ABS(B35)) -> 0 | C65: =MIN(255,ABS(C35)) -> 0 | D65: =MIN(255,ABS(D35)) -> 0 | E65: =MIN(255,ABS(E35)) -> 0 | F65: =MIN(255,ABS(F35)) -> 0 | G65: =MIN(255,ABS(G35)) -> 255 | H65: =MIN(255,ABS(H35)) -> 255 | ... AB65: =MIN(255,ABS(AB35)) -> 0
A66: =MIN(255,ABS(A36)) -> 0 | B66: =MIN(255,ABS(B36)) -> 0 | C66: =MIN(255,ABS(C36)) -> 0 | D66: =MIN(255,ABS(D36)) -> 0 | E66: =MIN(255,ABS(E36)) -> 0 | F66: =MIN(255,ABS(F36)) -> 255 | G66: =MIN(255,ABS(G36)) -> 255 | H66: =MIN(255,ABS(H36)) -> 255 | ... AB66: =MIN(255,ABS(AB36)) -> 0
A67: =MIN(255,ABS(A37)) -> 0 | B67: =MIN(255,ABS(B37)) -> 0 | C67: =MIN(255,ABS(C37)) -> 0 | D67: =MIN(255,ABS(D37)) -> 0 | E67: =MIN(255,ABS(E37)) -> 255 | F67: =MIN(255,ABS(F37)) -> 255 | G67: =MIN(255,ABS(G37)) -> 255 | H67: =MIN(255,ABS(H37)) -> 255 | ... AB67: =MIN(255,ABS(AB37)) -> 0
A68: =MIN(255,ABS(A38)) -> 0 | B68: =MIN(255,ABS(B38)) -> 0 | C68: =MIN(255,ABS(C38)) -> 0 | D68: =MIN(255,ABS(D38)) -> 255 | E68: =MIN(255,ABS(E38)) -> 255 | F68: =MIN(255,ABS(F38)) -> 255 | G68: =MIN(255,ABS(G38)) -> 255 | H68: =MIN(255,ABS(H38)) -> 0 | ... AB68: =MIN(255,ABS(AB38)) -> 0
A69: =MIN(255,ABS(A39)) -> 0 | B69: =MIN(255,ABS(B39)) -> 0 | C69: =MIN(255,ABS(C39)) -> 0 | D69: =MIN(255,ABS(D39)) -> 255 | E69: =MIN(255,ABS(E39)) -> 255 | F69: =MIN(255,ABS(F39)) -> 255 | G69: =MIN(255,ABS(G39)) -> 0 | H69: =MIN(255,ABS(H39)) -> 0 | ... AB69: =MIN(255,ABS(AB39)) -> 0
A70: =MIN(255,ABS(A40)) -> 0 | B70: =MIN(255,ABS(B40)) -> 0 | C70: =MIN(255,ABS(C40)) -> 0 | D70: =MIN(255,ABS(D40)) -> 255 | E70: =MIN(255,ABS(E40)) -> 255 | F70: =MIN(255,ABS(F40)) -> 255 | G70: =MIN(255,ABS(G40)) -> 0 | H70: =MIN(255,ABS(H40)) -> 0 | ... AB70: =MIN(255,ABS(AB40)) -> 0
A71: =MIN(255,ABS(A41)) -> 0 | B71: =MIN(255,ABS(B41)) -> 0 | C71: =MIN(255,ABS(C41)) -> 0 | D71: =MIN(255,ABS(D41)) -> 255 | E71: =MIN(255,ABS(E41)) -> 255 | F71: =MIN(255,ABS(F41)) -> 255 | G71: =MIN(255,ABS(G41)) -> 255 | H71: =MIN(255,ABS(H41)) -> 0 | ... AB71: =MIN(255,ABS(AB41)) -> 0
...

Sheet Resumen_Kernels
B2: Kernel | C2: Matriz | D2: Función | E2: Resultado observado | G2: Análisis de resultados
B3: Identidad | C3: 0 0 0 / 0 1 0 / 0 0 0 | D3: Mantener la imagen | E3: El corazón conserva su forma
B4: Detección de bordes | C4: -1 -1 -1 / -1 8 -1 / -1 -1 -1 | D4: Resaltar cambios de intensidad | E4: Se observa principalmente el contorno
B5: Media 3×3 | C5: 1/9 en las 9 posiciones | D5: Suavizar | E5: Aparecen grises y bordes menos definidos
B6: Kernel propio | C6: 0 -1 0 / -1 5 -1 / 0 -1 0 | D6: Realzar detalles | E6: Bordes más marcados
G26: Conclusiones
